Workbook

Sheet Summary Report

Sheet Data Descriptors 1
O1: RothIRA | U1: Investment income Export | AL1: FRED Graph Observations | AS1: FRED Graph Observations
O2: Monthly | P2: Beginning balance | Q2: Ending balance | R2: Returns | U2: Income For: 237906380 | AL2: Federal Reserve Economic Data, Federal Reserve Bank of St. Louis | AS2: Federal Reserve Economic Data, Federal Reserve Bank of St. Louis
O3: 44866 | P3: 1546.44 | Q3: 1569.76 | R3: =(Q3 - P3) / P3 -> 0.015079796 | U3: Investment income - (Sep-01-2022 - Oct-28-2025) | AL3: Link: https://fred.stlouisfed.org | AS3: Link: https://fred.stlouisfed.org
O4: 44896 | P4: 1569.76 | Q4: 1892.55 | R4: =(Q4 - P4) / P4 -> 0.20563016 | U4: Monthly | V4: Beginning balance | W4: Market change | X4: Dividends | Y4: Interest | Z4: Deposits | AA4: Withdrawals | AB4: Net advisory fees | AC4: Ending balance | AL4: Help: https://fredhelp.stlouisfed.org | AS4: Help: https://fredhelp.stlouisfed.org
O5: 44927 | P5: 1892.55 | Q5: 2115.6 | R5: =(Q5 - P5) / P5 -> 0.11785686 | U5: Oct 2025(As of Oct-28-2025) | V5: 3521.24 | W5: 58.36 | X5: 1.32 | Y5: 0 | Z5: 0 | AA5: 0 | AB5: 0 | AC5: 3581.14 | AD5: Ending balance: $3,580.92 Accrued interest and dividends: $0.22 (not yet paid) | AL5: This data may be copyrighted. Please refer to the Terms of Use: https://fred.stlouisfed.org/legal#fred-terms-faq | AS5: This data may be copyrighted. Please refer to the Terms of Use: https://fred.stlouisfed.org/legal#fred-terms-faq
O6: 44958 | P6: 2115.6 | Q6: 2069.23 | R6: =(Q6 - P6) / P6 -> -0.021918132 | U6: 45901 | V6: 3486.14 | W6: 32.36 | X6: 1.42 | Y6: 0 | Z6: 0 | AA6: 0 | AB6: 0 | AC6: 3521.24 | AD6: Ending balance: $3,519.92 Accrued interest and dividends: $1.32
O7: 44986 | P7: 2069.23 | Q7: 2155.73 | R7: =(Q7 - P7) / P7 -> 0.04180299 | U7: 45870 | V7: 3386.21 | W7: 95.38 | X7: 4.28 | Y7: 0 | Z7: 0 | AA7: 0 | AB7: 0 | AC7: 3486.14 | AD7: Ending balance: $3,485.87 Accrued interest and dividends: $0.27
A8: Roth IRA Returns | C8: 3mo T-Bills % 11/22 - 9/25 | E8: SP500 11/22 - 10/25 | G8: Portfolio Mean Excess Return | I8: S&P 500 1928 - 2024 | K8: 3-month T.Bill 1928 - 2024 | M8: Excess Monthly Returns | O8: 45017 | P8: 2155.73 | Q8: 2186.14 | R8: =(Q8 - P8) / P8 -> 0.01410659 | U8: 45839 | V8: 3482.13 | W8: -98.27 | X8: 2.1 | Y8: 0 | Z8: 0 | AA8: 0 | AB8: 0 | AC8: 3386.21 | AD8: Ending balance: $3,385.96 Accrued interest and dividends: $0.25 | AL8: observation_date | AM8: 3mo T-Bills % Returns | AN8: Monthly Returns | AS8: observation_date | AT8: SP500 | AU8: Monthly Returns | BA8: Historical Sharpe | BB8: Date | BC8: Portfolio Mean Excess Return | BE8: DowJones | BF8: {=_xlfn.STOCKHISTORY("^DJI", EDATE(DATE(2025, 10, 26),-36), TODAY(), 2, 1, 0, 1)} -> Date | BG8: Close | BH8: Returns
O9: 45047 | P9: 2186.14 | Q9: 2212.79 | R9: =(Q9 - P9) / P9 -> 0.012190436 | U9: 45809 | V9: 3536.27 | W9: -56.93 | X9: 1.59 | Y9: 0 | Z9: 0 | AA9: 0 | AB9: 0 | AC9: 3482.13 | AD9: Ending balance: $3,480.93 Accrued interest and dividends: $1.20 | AL9: 44866 | AM9: 4.32 | AN9: =((1 + AM9/100) ^ (1/12)) - 1 -> 0.0035306274 | AS9: 44835 | AT9: 3726.05 | BB9: 44866 | BC9: =R3 - AN9 -> 0.011549169 | BF9: 44835 | BG9: 32732.953
A10: Mean | B10: 0.02479555 | C10: 0.004028336 | E10: 0.016872518 | G10: 0.020989629 | H10: 0.020989629 | I10: 0.11794146 | J10: 0.11794146 | K10: 0.033552896 | L10: 0.033552896 | M10: 0.011162256 | O10: 45078 | P10: 2212.79 | Q10: 2326.05 | R10: =(Q10 - P10) / P10 -> 0.051184252 | U10: 45778 | V10: 3433.57 | W10: 97.86 | X10: 4.52 | Y10: 0 | Z10: 0 | AA10: 0 | AB10: 0 | AC10: 3536.27 | AD10: Ending balance: $3,535.95 Accrued interest and dividends: $0.32 | AL10: 44896 | AM10: 4.36 | AN10: =((1 + AM10/100) ^ (1/12)) - 1 -> 0.0035626875 | AS10: 44866 | AT10: 3917.49 | AU10: =(AT10-AT9)/AT9 -> 0.051378806 | BB10: 44896 | BC10: =R4 - AN10 -> 0.20206747 | BF10: 44866 | BG10: 34589.768 | BH10: =(BG10 - BG9) / BG9 -> 0.056726177
A11: Standard Error | B11: 0.0085101763 | C11: 7.0426164e-05 | E11: 0.0050192622 | G11: 0.008753382 | H11: 0.008753382 | I11: 0.019794105 | J11: 0.019794105 | K11: 0.0030423803 | L11: 0.0030423803 | M11: 0.006086532 | O11: 45108 | P11: 2326.05 | Q11: 2386.7 | R11: =(Q11 - P11) / P11 -> 0.026074246 | U11: 45748 | V11: 3387.16 | W11: 44.25 | X11: 1.89 | Y11: 0 | Z11: 0 | AA11: 0 | AB11: 0 | AC11: 3433.57 | AD11: Ending balance: $3,433.30 Accrued interest and dividends: $0.27 | AL11: 44927 | AM11: 4.69 | AN11: =((1 + AM11/100) ^ (1/12)) - 1 -> 0.0038267548 | AS11: 44896 | AT11: 3912.38 | AU11: =(AT11-AT10)/AT10 -> -0.0013044066 | BB11: 44927 | BC11: =R5 - AN11 -> 0.11403011 | BF11: 44896 | BG11: 33147.249 | BH11: =(BG11 - BG10) / BG10 -> -0.041703662
A12: Median | B12: 0.016045423 | C12: 0.0040103508 | E12: 0.023881732 | G12: 0.011549169 | H12: 0.011549169 | I12: 0.14821092 | J12: 0.14821092 | K12: 0.0299712 | L12: 0.0299712 | M12: 0.018818235 | O12: 45139 | P12: 2386.7 | Q12: 2325.78 | R12: =(Q12 - P12) / P12 -> -0.025524783 | U12: 45717 | V12: 3674.3 | W12: -289.9 | X12: 1.96 | Y12: 0 | Z12: 0 | AA12: 0 | AB12: 0 | AC12: 3387.16 | AD12: Ending balance: $3,386.36 Accrued interest and dividends: $0.80 | AL12: 44958 | AM12: 4.79 | AN12: =((1 + AM12/100) ^ (1/12)) - 1 -> 0.0039066245 | AS12: 44927 | AT12: 3960.66 | AU12: =(AT12-AT11)/AT11 -> 0.012340315 | BB12: 44958 | BC12: =R6 - AN12 -> -0.025824756 | BF12: 44927 | BG12: 34086.037 | BH12: =(BG12 - BG11) / BG11 -> 0.02832175
A13: Mode | B13: #N/A | C13: 0.0044240812 | E13: #N/A | G13: #N/A | H13: #N/A | I13: #N/A | J13: #N/A | K13: 0.0038 | L13: 0.0038 | M13: #N/A | O13: 45170 | P13: 2325.78 | Q13: 2301.77 | R13: =(Q13 - P13) / P13 -> -0.010323418 | U13: 45689 | V13: 3535.45 | W13: 134.13 | X13: 4.06 | Y13: 0 | Z13: 0 | AA13: 0 | AB13: 0 | AC13: 3674.3 | AD13: Ending balance: $3,673.64 Accrued interest and dividends: $0.66 | AL13: 44986 | AM13: 4.86 | AN13: =((1 + AM13/100) ^ (1/12)) - 1 -> 0.0039624918 | AS13: 44958 | AT13: 4079.68 | AU13: =(AT13-AT12)/AT12 -> 0.030050547 | BB13: 44986 | BC13: =R7 - AN13 -> 0.037840498 | BF13: 44958 | BG13: 32656.698 | BH13: =(BG13 - BG12) / BG12 -> -0.041933259
A14: Standard Deviation | B14: 0.051061058 | C14: 0.00041664681 | E14: 0.030115573 | G14: 0.051785706 | H14: 0.051785706 | I14: 0.19494933 | J14: 0.19494933 | K14: 0.029963971 | L14: 0.029963971 | M14: 0.036519192 | O14: 45200 | P14: 2301.77 | Q14: 2267.09 | R14: =(Q14 - P14) / P14 -> -0.015066666 | U14: 45658 | V14: 3393.34 | W14: 139.55 | X14: 2.33 | Y14: 0 | Z14: 0 | AA14: 0 | AB14: 0 | AC14: 3535.45 | AD14: Ending balance: $3,535.22 Accrued interest and dividends: $0.23 | AL14: 45017 | AM14: 5.07 | AN14: =((1 + AM14/100) ^ (1/12)) - 1 -> 0.0041298886 | AS14: 44986 | AT14: 3968.56 | AU14: =(AT14-AT13)/AT13 -> -0.02723743 | BB14: 45017 | BC14: =R8 - AN14 -> 0.0099767017 | BF14: 44986 | BG14: 33274.154 | BH14: =(BG14 - BG13) / BG13 -> 0.018907472
A15: Sample Variance | B15: 0.0026072316 | C15: 1.7359456e-07 | E15: 0.00090694776 | G15: 0.0026817594 | H15: 0.0026817594 | I15: 0.03800524 | J15: 0.03800524 | K15: 0.00089783955 | L15: 0.00089783955 | M15: 0.0013336514 | O15: 45231 | P15: 2267.09 | Q15: 2434.63 | R15: =(Q15 - P15) / P15 -> 0.073900904 | U15: 45627 | V15: 3509.86 | W15: -119.5 | X15: 1.76 | Y15: 0 | Z15: 0 | AA15: 0 | AB15: 0 | AC15: 3393.34 | AD15: Ending balance: $3,392.12 Accrued interest and dividends: $1.22 | AL15: 45047 | AM15: 5.31 | AN15: =((1 + AM15/100) ^ (1/12)) - 1 -> 0.0043208242 | AS15: 45017 | AT15: 4121.47 | AU15: =(AT15-AT14)/AT14 -> 0.038530349 | BB15: 45047 | BC15: =R9 - AN15 -> 0.0078696119 | BF15: 45017 | BG15: 34098.164 | BH15: =(BG15 - BG14) / BG14 -> 0.024764266
A16: Kurtosis | B16: 3.4740854 | C16: -1.7376689 | E16: 0.69584168 | G16: 3.3347884 | H16: 3.3347884 | I16: 0.063145411 | J16: 0.063145411 | K16: 0.94965073 | L16: 0.94965073 | M16: -0.72770661 | O16: 45261 | P16: 2434.63 | Q16: 2647.42 | R16: =(Q16 - P16) / P16 -> 0.087401371 | U16: 45597 | V16: 3254.02 | W16: 251.4 | X16: 4.17 | Y16: 0 | Z16: 0 | AA16: 0 | AB16: 0 | AC16: 3509.86 | AD16: Ending balance: $3,509.59 Accrued interest and dividends: $0.27 | AL16: 45078 | AM16: 5.42 | AN16: =((1 + AM16/100) ^ (1/12)) - 1 -> 0.0044082031 | AS16: 45047 | AT16: 4146.17 | AU16: =(AT16-AT15)/AT15 -> 0.0059930073 | BB16: 45078 | BC16: =R10 - AN16 -> 0.046776048 | BF16: 45047 | BG16: 32908.267 | BH16: =(BG16 - BG15) / BG15 -> -0.034896196
A17: Skewness | B17: 1.2444711 | C17: -0.14071022 | E17: -0.68834978 | G17: 1.2282907 | H17: 1.2282907 | I17: -0.45501636 | J17: -0.45501636 | K17: 1.0164243 | L17: 1.0164243 | M17: -0.14258485 | O17: 45292 | P17: 2647.42 | Q17: 2699.74 | R17: =(Q17 - P17) / P17 -> 0.019762637 | U17: 45566 | V17: 3309.42 | W17: -57.87 | X17: 2.47 | Y17: 0 | Z17: 0 | AA17: 0 | AB17: 0 | AC17: 3254.02 | AD17: Ending balance: $3,254.02 Accrued interest and dividends: $0.00 | AL17: 45108 | AM17: 5.49 | AN17: =((1 + AM17/100) ^ (1/12)) - 1 -> 0.0044637644 | AS17: 45078 | AT17: 4345.37 | AU17: =(AT17-AT16)/AT16 -> 0.04804434 | BB17: 45108 | BC17: =R11 - AN17 -> 0.021610482 | BF17: 45078 | BG17: 34407.6 | BH17: =(BG17 - BG16) / BG16 -> 0.045560967
A18: Range | B18: 0.28377838 | C18: 0.0012210108 | E18: 0.14094833 | G18: 0.28376235 | H18: 0.28376235 | I18: 0.9640087 | J18: 0.9640087 | K18: 0.14003465 | L18: 0.14003465 | M18: 0.1403704 | O18: 45323 | P18: 2699.74 | Q18: 2846.65 | R18: =(Q18 - P18) / P18 -> 0.054416351 | U18: 45536 | V18: 3282.91 | W18: 24.71 | X18: 1.8 | Y18: 0 | Z18: 0 | AA18: 0 | AB18: 0 | AC18: 3309.42 | AD18: Ending balance: $3,309.42 Accrued interest and dividends: $0.00 | AL18: 45139 | AM18: 5.56 | AN18: =((1 + AM18/100) ^ (1/12)) - 1 -> 0.0045192918 | AS18: 45108 | AT18: 4508.08 | AU18: =(AT18-AT17)/AT17 -> 0.037444452 | BB18: 45139 | BC18: =R12 - AN18 -> -0.030044075 | BF18: 45108 | BG18: 35559.533 | BH18: =(BG18 - BG17) / BG17 -> 0.033479037
A19: Minimum | B19: -0.078148219 | C19: 0.0033299958 | E19: -0.058739561 | G19: -0.081694878 | H19: -0.081694878 | I19: -0.43837549 | J19: -0.43837549 | K19: 0.0003272 | L19: 0.0003272 | M19: -0.052691956 | O19: 45352 | P19: 2846.65 | Q19: 2816.97 | R19: =(Q19 - P19) / P19 -> -0.010426291 | U19: 45505 | V19: 3114.82 | W19: 163.7 | X19: 4.39 | Y19: 0 | Z19: 0 | AA19: 0 | AB19: 0 | AC19: 3282.91 | AD19: Ending balance: $3,282.91 Accrued interest and dividends: $0.00 | AL19: 45170 | AM19: 5.56 | AN19: =((1 + AM19/100) ^ (1/12)) - 1 -> 0.0045192918 | AS19: 45139 | AT19: 4457.36 | AU19: =(AT19-AT18)/AT18 -> -0.011250909 | BB19: 45170 | BC19: =R13 - AN19 -> -0.01484271 | BF19: 45139 | BG19: 34721.913 | BH19: =(BG19 - BG18) / BG18 -> -0.023555425
A20: Maximum | B20: 0.20563016 | C20: 0.0045510066 | E20: 0.082208772 | G20: 0.20206747 | H20: 0.20206747 | I20: 0.52563321 | J20: 0.52563321 | K20: 0.14036185 | L20: 0.14036185 | M20: 0.087678441 | O20: 45383 | P20: 2816.97 | Q20: 2744.78 | R20: =(Q20 - P20) / P20 -> -0.025626826 | U20: 45474 | V20: 3116.05 | W20: -3.4 | X20: 2.17 | Y20: 0 | Z20: 0 | AA20: 0 | AB20: 0 | AC20: 3114.82 | AD20: Ending balance: $3,114.82 Accrued interest and dividends: $0.00 | AL20: 45200 | AM20: 5.6 | AN20: =((1 + AM20/100) ^ (1/12)) - 1 -> 0.0045510066 | AS20: 45170 | AT20: 4409.1 | AU20: =(AT20-AT19)/AT19 -> -0.010827037 | BB20: 45200 | BC20: =R14 - AN20 -> -0.019617673 | BF20: 45170 | BG20: 33507.499 | BH20: =(BG20 - BG19) / BG19 -> -0.034975429
A21: Sum | B21: 0.89263981 | C21: 0.14099176 | E21: 0.60741063 | G21: 0.734637 | H21: 0.734637 | I21: 11.440321 | J21: 11.440321 | K21: 3.2546309 | L21: 3.2546309 | M21: 0.40184123 | O21: 45413 | P21: 2744.78 | Q21: 2986.15 | R21: =(Q21 - P21) / P21 -> 0.087937831 | U21: 45444 | V21: 2986.15 | W21: 127.85 | X21: 2.05 | Y21: 0 | Z21: 0 | AA21: 0 | AB21: 0 | AC21: 3116.05 | AD21: Ending balance: $3,116.05 Accrued interest and dividends: $0.00 | AL21: 45231 | AM21: 5.52 | AN21: =((1 + AM21/100) ^ (1/12)) - 1 -> 0.004487566 | AS21: 45200 | AT21: 4269.4 | AU21: =(AT21-AT20)/AT20 -> -0.031684471 | BB21: 45231 | BC21: =R15 - AN21 -> 0.069413338 | BF21: 45200 | BG21: 33052.869 | BH21: =(BG21 - BG20) / BG20 -> -0.013568031
A22: Count | B22: 36 | C22: 35 | E22: 36 | G22: 35 | H22: 35 | I22: 97 | J22: 97 | K22: 97 | L22: 97 | M22: 36 | O22: 45444 | P22: 2986.15 | Q22: 3116.05 | R22: =(Q22 - P22) / P22 -> 0.043500829 | U22: 45413 | V22: 2744.78 | W22: 236.42 | X22: 4.36 | Y22: 0 | Z22: 0 | AA22: 0 | AB22: 0 | AC22: 2986.15 | AD22: Ending balance: $2,985.56 Accrued interest and dividends: $0.59 | AL22: 45261 | AM22: 5.44 | AN22: =((1 + AM22/100) ^ (1/12)) - 1 -> 0.0044240812 | AS22: 45231 | AT22: 4460.06 | AU22: =(AT22-AT21)/AT21 -> 0.044657329 | BB22: 45261 | BC22: =R16 - AN22 -> 0.08297729 | BF22: 45231 | BG22: 35950.893 | BH22: =(BG22 - BG21) / BG21 -> 0.087678441
A23: Confidence Level(95.0%) | B23: 0.017276576 | C23: 0.00014312319 | E23: 0.010189644 | G23: 0.017789013 | H23: 0.017789013 | I23: 0.039290988 | J23: 0.039290988 | K23: 0.0060390771 | L23: 0.0060390771 | M23: 0.012356317 | O23: 45474 | P23: 3116.05 | Q23: 3114.82 | R23: =(Q23 - P23) / P23 -> -0.00039473051 | U23: 45383 | V23: 2816.97 | W23: -76.92 | X23: 2.15 | Y23: 0 | Z23: 0 | AA23: 0 | AB23: 0 | AC23: 2744.78 | AD23: Ending balance: $2,742.20 Accrued interest and dividends: $2.58 | AL23: 45292 | AM23: 5.45 | AN23: =((1 + AM23/100) ^ (1/12)) - 1 -> 0.0044320192 | AS23: 45261 | AT23: 4685.05 | AU23: =(AT23-AT22)/AT22 -> 0.05044551 | BB23: 45292 | BC23: =R17 - AN23 -> 0.015330618 | BF23: 45261 | BG23: 37689.536 | BH23: =(BG23 - BG22) / BG22 -> 0.048361609
O24: 45505 | P24: 3114.82 | Q24: 3282.91 | R24: =(Q24 - P24) / P24 -> 0.053964595 | U24: 45352 | V24: 2846.65 | W24: -32.7 | X24: 2.09 | Y24: 0 | Z24: 0 | AA24: 0 | AB24: 0 | AC24: 2816.97 | AD24: Ending balance: $2,816.04 Accrued interest and dividends: $0.93 | AL24: 45323 | AM24: 5.44 | AN24: =((1 + AM24/100) ^ (1/12)) - 1 -> 0.0044240812 | AS24: 45292 | AT24: 4804.49 | AU24: =(AT24-AT23)/AT23 -> 0.025493858 | BB24: 45323 | BC24: =R18 - AN24 -> 0.04999227 | BF24: 45292 | BG24: 38150.296 | BH24: =(BG24 - BG23) / BG23 -> 0.012225147
O25: 45536 | P25: 3282.91 | Q25: 3309.42 | R25: =(Q25 - P25) / P25 -> 0.0080751528 | U25: 45323 | V25: 2699.74 | W25: 142.35 | X25: 3.95 | Y25: 0 | Z25: 0 | AA25: 0 | AB25: 0 | AC25: 2846.65 | AD25: Ending balance: $2,846.04 Accrued interest and dividends: $0.61 | AL25: 45352 | AM25: 5.47 | AN25: =((1 + AM25/100) ^ (1/12)) - 1 -> 0.0044478932 | AS25: 45323 | AT25: 5011.96 | AU25: =(AT25-AT24)/AT24 -> 0.043182523 | BB25: 45352 | BC25: =R19 - AN25 -> -0.014874184 | BF25: 45323 | BG25: 38996.385 | BH25: =(BG25 - BG24) / BG24 -> 0.022177802
O26: 45566 | P26: 3309.42 | Q26: 3254.02 | R26: =(Q26 - P26) / P26 -> -0.016740093 | U26: 45292 | V26: 2647.42 | W26: 20 | X26: 32.05 | Y26: 0 | Z26: 0 | AA26: 0 | AB26: 0 | AC26: 2699.74 | AD26: Ending balance: $2,699.47 Accrued interest and dividends: $0.27 | AL26: 45383 | AM26: 5.44 | AN26: =((1 + AM26/100) ^ (1/12)) - 1 -> 0.0044240812 | AS26: 45352 | AT26: 5170.57 | AU26: =(AT26-AT25)/AT25 -> 0.031646302 | BB26: 45383 | BC26: =R20 - AN26 -> -0.030050907 | BF26: 45352 | BG26: 39807.374 | BH26: =(BG26 - BG25) / BG25 -> 0.020796517
O27: 45597 | P27: 3254.02 | Q27: 3509.86 | R27: =(Q27 - P27) / P27 -> 0.07862275 | U27: 45261 | V27: 2434.63 | W27: 179.9 | X27: 2.03 | Y27: 0 | Z27: 0 | AA27: 0 | AB27: 0 | AC27: 2647.42 | AD27: Ending balance: $2,616.56 Accrued interest and dividends: $30.86 | AL27: 45413 | AM27: 5.46 | AN27: =((1 + AM27/100) ^ (1/12)) - 1 -> 0.0044399565 | AS27: 45383 | AT27: 5112.49 | AU27: =(AT27-AT26)/AT26 -> -0.011232804 | BB27: 45413 | BC27: =R21 - AN27 -> 0.083497875 | BF27: 45383 | BG27: 37815.916 | BH27: =(BG27 - BG26) / BG26 -> -0.050027376
O28: 45627 | P28: 3509.86 | Q28: 3393.34 | R28: =(Q28 - P28) / P28 -> -0.033197905 | U28: 45231 | V28: 2267.09 | W28: 163.01 | X28: 3.82 | Y28: 0 | Z28: 0 | AA28: 0 | AB28: 0 | AC28: 2434.63 | AD28: Ending balance: $2,433.92 Accrued interest and dividends: $0.71 | AL28: 45444 | AM28: 5.51 | AN28: =((1 + AM28/100) ^ (1/12)) - 1 -> 0.0044796328 | AS28: 45413 | AT28: 5235.23 | AU28: =(AT28-AT27)/AT27 -> 0.024007871 | BB28: 45444 | BC28: =R22 - AN28 -> 0.039021196 | BF28: 45413 | BG28: 38686.322 | BH28: =(BG28 - BG27) / BG27 -> 0.02301692
O29: 45658 | P29: 3393.34 | Q29: 3535.45 | R29: =(Q29 - P29) / P29 -> 0.041879093 | U29: 45200 | V29: 2301.77 | W29: -36.93 | X29: 2 | Y29: 0 | Z29: 0 | AA29: 0 | AB29: 0 | AC29: 2267.09 | AD29: Ending balance: $2,266.84 Accrued interest and dividends: $0.25 | AL29: 45474 | AM29: 5.43 | AN29: =((1 + AM29/100) ^ (1/12)) - 1 -> 0.0044161425 | AS29: 45444 | AT29: 5415.14 | AU29: =(AT29-AT28)/AT28 -> 0.034365252 | BB29: 45474 | BC29: =R23 - AN29 -> -0.004810873 | BF29: 45444 | BG29: 39118.864 | BH29: =(BG29 - BG28) / BG28 -> 0.011180755
O30: 45689 | P30: 3535.45 | Q30: 3674.3 | R30: =(Q30 - P30) / P30 -> 0.039273643 | U30: 45170 | V30: 2325.78 | W30: -28.71 | X30: 3.78 | Y30: 0 | Z30: 0 | AA30: 0 | AB30: 0 | AC30: 2301.77 | AD30: Ending balance: $2,300.85 Accrued interest and dividends: $0.92 | AL30: 45505 | AM30: 5.3 | AN30: =((1 + AM30/100) ^ (1/12)) - 1 -> 0.0043128766 | AS30: 45474 | AT30: 5538 | AU30: =(AT30-AT29)/AT29 -> 0.022688241 | BB30: 45505 | BC30: =R24 - AN30 -> 0.049651719 | BF30: 45474 | BG30: 40842.792 | BH30: =(BG30 - BG29) / BG29 -> 0.044068971
O31: 45717 | P31: 3674.3 | Q31: 3387.16 | R31: =(Q31 - P31) / P31 -> -0.078148219 | U31: 45139 | V31: 2386.7 | W31: -65.33 | X31: 1.86 | Y31: 0 | Z31: 0 | AA31: 0 | AB31: 0 | AC31: 2325.78 | AD31: Ending balance: $2,323.23 Accrued interest and dividends: $2.55 | AL31: 45536 | AM31: 4.92 | AN31: =((1 + AM31/100) ^ (1/12)) - 1 -> 0.0040103508 | AS31: 45505 | AT31: 5478.21 | AU31: =(AT31-AT30)/AT30 -> -0.010796316 | BB31: 45536 | BC31: =R25 - AN31 -> 0.0040648021 | BF31: 45505 | BG31: 41563.08 | BH31: =(BG31 - BG30) / BG30 -> 0.017635614
O32: 45748 | P32: 3387.16 | Q32: 3433.57 | R32: =(Q32 - P32) / P32 -> 0.013701744 | U32: 45108 | V32: 2326.05 | W32: 58.54 | X32: 1.78 | Y32: 0 | Z32: 0 | AA32: 0 | AB32: 0 | AC32: 2386.7 | AD32: Ending balance: $2,386.37 Accrued interest and dividends: $0.33 | AL32: 45566 | AM32: 4.72 | AN32: =((1 + AM32/100) ^ (1/12)) - 1 -> 0.003850723 | AS32: 45536 | AT32: 5621.26 | AU32: =(AT32-AT31)/AT31 -> 0.026112544 | BB32: 45566 | BC32: =R26 - AN32 -> -0.020590816 | BF32: 45536 | BG32: 42330.15 | BH32: =(BG32 - BG31) / BG31 -> 0.018455562
O33: 45778 | P33: 3433.57 | Q33: 3536.27 | R33: =(Q33 - P33) / P33 -> 0.02991056 | U33: 45078 | V33: 2212.79 | W33: 110.56 | X33: 1.92 | Y33: 0 | Z33: 0 | AA33: 0 | AB33: 0 | AC33: 2326.05 | AD33: Ending balance: $2,325.27 Accrued interest and dividends: $0.78 | AL33: 45597 | AM33: 4.62 | AN33: =((1 + AM33/100) ^ (1/12)) - 1 -> 0.0037708043 | AS33: 45566 | AT33: 5792.32 | AU33: =(AT33-AT32)/AT32 -> 0.0304309 | BB33: 45597 | BC33: =R27 - AN33 -> 0.074851945 | BF33: 45566 | BG33: 41763.46 | BH33: =(BG33 - BG32) / BG32 -> -0.013387385
O34: 45809 | P34: 3536.27 | Q34: 3482.13 | R34: =(Q34 - P34) / P34 -> -0.015309917 | U34: 45047 | V34: 2186.14 | W34: 22.19 | X34: 3.67 | Y34: 0 | Z34: 0 | AA34: 0 | AB34: 0 | AC34: 2212.79 | AD34: Ending balance: $2,212.00 Accrued interest and dividends: $0.79 | AL34: 45627 | AM34: 4.39 | AN34: =((1 + AM34/100) ^ (1/12)) - 1 -> 0.0035867252 | AS34: 45597 | AT34: 5929.92 | AU34: =(AT34-AT33)/AT33 -> 0.023755594 | BB34: 45627 | BC34: =R28 - AN34 -> -0.036784631 | BF34: 45597 | BG34: 44910.65 | BH34: =(BG34 - BG33) / BG33 -> 0.075357502
O35: 45839 | P35: 3482.13 | Q35: 3386.21 | R35: =(Q35 - P35) / P35 -> -0.027546358 | U35: 45017 | V35: 2155.73 | W35: 28.49 | X35: 1.74 | Y35: 0 | Z35: 0 | AA35: 0 | AB35: 0 | AC35: 2186.14 | AD35: Ending balance: $2,185.96 Accrued interest and dividends: $0.18 | AL35: 45658 | AM35: 4.34 | AN35: =((1 + AM35/100) ^ (1/12)) - 1 -> 0.0035466589 | AS35: 45627 | AT35: 6010.91 | AU35: =(AT35-AT34)/AT34 -> 0.013657857 | BB35: 45658 | BC35: =R29 - AN35 -> 0.038332434 | BF35: 45627 | BG35: 42544.22 | BH35: =(BG35 - BG34) / BG34 -> -0.052691956
... O37: 45901 | P37: 3486.14 | Q37: 3521.24 | R37: =(Q37 - P37) / P37 -> 0.010068442 | U37: 44958 | V37: 2115.6 | W37: -50.22 | X37: 3.3 | Y37: 0 | Z37: 0 | AA37: 0 | AB37: 0 | AC37: 2069.23 | AD37: Ending balance: $2,068.68 Accrued interest and dividends: $0.55 | AL37: 45717 | AM37: 4.34 | AN37: =((1 + AM37/100) ^ (1/12)) - 1 -> 0.0035466589 | AS37: 45689 | AT37: 6038.69 | AU37: =(AT37-AT36)/AT36 -> 0.0098954431 | BB37: 45717 | BC37: =R31 - AN37 -> -0.081694878 | BF37: 45689 | BG37: 43840.91 | BH37: =(BG37 - BG36) / BG36 -> -0.015798751
O38: As of Oct-28-2025 | P38: 3521.24 | Q38: 3581.14 | R38: 0.01701105 | U38: 44927 | V38: 1892.55 | W38: 221.36 | X38: 1.41 | Y38: 0 | Z38: 0 | AA38: 0 | AB38: 0 | AC38: 2115.6 | AD38: Ending balance: $2,115.32 Accrued interest and dividends: $0.28 | AL38: 45748 | AM38: 4.32 | AN38: =((1 + AM38/100) ^ (1/12)) - 1 -> 0.0035306274 | AS38: 45717 | AT38: 5683.98 | AU38: =(AT38-AT37)/AT37 -> -0.058739561 | BB38: 45748 | BC38: =R32 - AN38 -> 0.010171117 | BF38: 45717 | BG38: 42001.76 | BH38: =(BG38 - BG37) / BG37 -> -0.041950543
U39: 44896 | V39: 1569.76 | W39: -74.31 | X39: 3.21 | Y39: 0 | Z39: 393.14 | AA39: 0 | AB39: 0 | AC39: 1892.55 | AD39: Ending balance: $1,891.80 Accrued interest and dividends: $0.75 | AL39: 45778 | AM39: 4.36 | AN39: =((1 + AM39/100) ^ (1/12)) - 1 -> 0.0035626875 | AS39: 45748 | AT39: 5369.5 | AU39: =(AT39-AT38)/AT38 -> -0.055327429 | BB39: 45778 | BC39: =R33 - AN39 -> 0.026347872 | BF39: 45748 | BG39: 40669.36 | BH39: =(BG39 - BG38) / BG38 -> -0.03172248
U40: 44866 | V40: 1546.44 | W40: 20.08 | X40: 2.56 | Y40: 0 | Z40: 0 | AA40: 0 | AB40: 0 | AC40: 1569.76 | AD40: Ending balance: $1,569.08 Accrued interest and dividends: $0.68 | AL40: 45809 | AM40: 4.42 | AN40: =((1 + AM40/100) ^ (1/12)) - 1 -> 0.0036107566 | AS40: 45778 | AT40: 5810.92 | AU40: =(AT40-AT39)/AT39 -> 0.082208772 | BB40: 45809 | BC40: =R34 - AN40 -> -0.018920674 | BF40: 45778 | BG40: 42270.07 | BH40: =(BG40 - BG39) / BG39 -> 0.039359115
U41: 44835 | V41: 490.41 | W41: 53.99 | X41: 1.86 | Y41: 0 | Z41: 1000 | AA41: 0 | AB41: 0 | AC41: 1546.44 | AD41: Ending balance: $1,546.26 Accrued interest and dividends: $0.18 | AL41: 45839 | AM41: 4.41 | AN41: =((1 + AM41/100) ^ (1/12)) - 1 -> 0.0036027469 | AS41: 45809 | AT41: 6029.95 | AU41: =(AT41-AT40)/AT40 -> 0.037692827 | BB41: 45839 | BC41: =R35 - AN41 -> -0.031149105 | BF41: 45809 | BG41: 44094.77 | BH41: =(BG41 - BG40) / BG40 -> 0.04316766
...

Sheet Data Descriptors 2
A1: Date updated: | B1: 45658
A2: Created by: | B2: Aswath Damodaran, adamodar@stern.nyu.edu
A3: What is this data? | B3: Historical returns: Stocks, Bonds & T.Bills with premiums | I3: In US Dollars
A4: Home Page: | B4: https://pages.stern.nyu.edu/~adamodar/
A5: Data website: | B5: https://pages.stern.nyu.edu/~adamodar/New_Home_Page/data.html
A6: Companies in each industry: | B6: https://pages.stern.nyu.edu/~adamodar/pc/datasets/indname.xls
A7: Variable definitions: | B7: https://pages.stern.nyu.edu/~adamodar/New_Home_Page/datafile/variable.htm
A8: Customized Geometric risk premium estimator
A9: What is your riskfree rate? | D9: LT | G9: Estimates of risk premiums from 1928, over the last 50 years and over the last 10 years
A10: Enter your starting year | D10: 2014
A12: Value of stocks in starting year: | E12: =IF(D10=1928,100,VLOOKUP(D10-1,A21:O117,9)) -> 255553.31
A13: Value of T.Bills in starting year: | E13: =IF(D10=1928,100,VLOOKUP(D10-1,A21:L117,11)) -> 1982.0113
A14: Value of T.bonds in starting year: | E14: =IF(D10=1928,100,VLOOKUP(D10-1,A20:L117,12)) -> 6295.7854
A15: Value of Real estate in starting year | E15: =IF(D10=1928,100,VLOOKUP(D10-1,A20:N117,14)) -> 2728.3897
A16: Value of Gold in starting year | E16: =IF(D10=1928,100,VLOOKUP(D10-1,A20:O117,15)) -> 5835.7558
A17: Estimate of risk premium based on your inputs: | E17: =IF(D9="ST",(I117/E12)^(1/(A117-D10+1))-(K117/E13)^(1/(A117-D10+1)),(I117/E12)^(1/(A117-D10+1))-(L117/E14)^(1/(A117-D10+1))) -> 0.11851184
B19: Annual Returns on Investments in | I19: Value of $100 invested at start of 1928 in | P19: Annual Risk Premium | U19: Annual Real Returns | AC19: Value of $100 invested at start of 1928 in real terms | AJ19: Real Risk Premium
A20: Year | B20: S&P 500 (includes dividends) | C20: US Small cap (bottom decile) | D20: 3-month T.Bill | E20: US T. Bond (10-year) | F20: Baa Corporate Bond | G20: Real Estate | H20: Gold* | I20: S&P 500 (includes dividends)3 | J20: US Small cap (bottom decile) Cum Value | K20: 3-month T.Bill4 | L20: US T. Bond5 | M20: Baa Corporate Bond2 | N20: Real Estate2 | O20: Gold2 | P20: Stocks - Bills | Q20: Stocks - Bonds | R20: Small Cap Premium (S&P 500 minus Bottom Decile) | S20: Stocks - Baa Corp Bond | T20: Historical ERP | U20: Inflation Rate | V20: S&P 500 (includes dividends)2 | W20: US Small cap (bottom decile)22 | X20: 3-month T. Bill (Real) | Y20: !0-year T.Bonds | Z20: Baa Corp Bonds | AA20: Real Estate3 | AB20: Gold | AC20: S&P 500 (includes dividends)3 | AD20: US Small cap (bottom decile)22 | AE20: 3-month T.Bill4 | AF20: US T. Bond5 | AG20: Baa Corporate Bond2 | AH20: Real Estate2 | AI20: Gold2 | AJ20: Stocks minus T. Bills | AK20: Stocks minus T.Bonds
A21: 1928 | B21: =('[1]S&P 500 & Raw Data'!B4-'[1]S&P 500 & Raw Data'!B3+'[1]S&P 500 & Raw Data'!C4)/'[1]S&P 500 & Raw Data'!B3 -> 0.43811155 | C21: ='[1]Small Cap'!B2 -> 0.5991 | D21: 0.0308 | E21: ='[1]S&P 500 & Raw Data'!F4 -> 0.0083547086 | F21: ='[1]S&P 500 & Raw Data'!J4 -> 0.032195515 | G21: ='[1]Home Prices'!B4/'[1]Home Prices'!B3-1 -> 0.014910537 | H21: ='[1]Gold Prices'!B3/'[1]Gold Prices'!B2-1 -> 0.00096899225 | I21: =100*(1+B21) -> 143.81116 | J21: 159.91 | K21: =100*(1+D21) -> 103.08 | L21: =100*(1+E21) -> 100.83547 | M21: =100*(1+F21) -> 103.21955 | N21: =100*(1+G21) -> 101.49105 | O21: =100*(1+H21) -> 100.0969 | P21: =B21-D21 -> 0.40731155 | Q21: =B21-E21 -> 0.42975684 | R21: ='Data Descriptors 2'!$C21-'Data Descriptors 2'!$B21 -> 0.16098845 | S21: =B21-F21 -> 0.40591604 | U21: ='[1]Inflation Rate'!C26 -> -0.0115607 | V21: =(1+B21)/(1+$U21)-1 -> 0.45493158 | W21: =(1+C21)/(1+$U21)-1 -> 0.61780293 | X21: =(1+D21)/(1+$U21)-1 -> 0.042856147 | Y21: =(1+E21)/(1+$U21)-1 -> 0.020148337 | Z21: =(1+F21)/(1+$U21)-1 -> 0.044267984 | AA21: =(1+G21)/(1+$U21)-1 -> 0.026780842 | AB21: =(1+H21)/(1+$U21)-1 -> 0.012676238 | AC21: =100*(1+V21) -> 145.49316 | AD21: =100*(1+W21) -> 161.78029 | AE21: =100*(1+X21) -> 104.28561 | AF21: =100*(1+Y21) -> 102.01483 | AG21: =100*(1+Z21) -> 104.4268 | AH21: =100*(1+AA21) -> 102.67808 | AI21: =100*(1+AB21) -> 101.26762 | AJ21: ='Data Descriptors 2'!$V21-'Data Descriptors 2'!$X21 -> 0.41207543 | AK21: ='Data Descriptors 2'!$V21-'Data Descriptors 2'!$Y21 -> 0.43478324
A22: 1929 | B22: =('[1]S&P 500 & Raw Data'!B5-'[1]S&P 500 & Raw Data'!B4+'[1]S&P 500 & Raw Data'!C5)/'[1]S&P 500 & Raw Data'!B4 -> -0.082979466 | C22: ='[1]Small Cap'!B3 -> -0.4661 | D22: 0.0316 | E22: ='[1]S&P 500 & Raw Data'!F5 -> 0.042038042 | F22: ='[1]S&P 500 & Raw Data'!J5 -> 0.030178562 | G22: ='[1]Home Prices'!B5/'[1]Home Prices'!B4-1 -> -0.020568071 | H22: ='[1]Gold Prices'!B4/'[1]Gold Prices'!B3-1 -> -0.0014520813 | I22: =I21*(1+B22) -> 131.87778 | J22: =J21*(1+C22) -> 85.375949 | K22: =K21*(1+D22) -> 106.33733 | L22: =L21*(1+E22) -> 105.0744 | M22: =M21*(1+F22) -> 106.33457 | N22: =N21*(1+G22) -> 99.403579 | O22: =O21*(1+H22) -> 99.95155 | P22: =B22-D22 -> -0.11457947 | Q22: =B22-E22 -> -0.12501751 | R22: ='Data Descriptors 2'!$C22-'Data Descriptors 2'!$B22 -> -0.38312053 | S22: =B22-F22 -> -0.11315803 | U22: ='[1]Inflation Rate'!C27 -> 0.005848 | V22: =(1+B22)/(1+$U22)-1 -> -0.088311023 | W22: =(1+C22)/(1+$U22)-1 -> -0.46920409 | X22: =(1+D22)/(1+$U22)-1 -> 0.025602278 | Y22: =(1+E22)/(1+$U22)-1 -> 0.035979633 | Z22: =(1+F22)/(1+$U22)-1 -> 0.024189105 | AA22: =(1+G22)/(1+$U22)-1 -> -0.026262487 | AB22: =(1+H22)/(1+$U22)-1 -> -0.0072576386 | AC22: =AC21*(1+V22) -> 132.64451 | AD22: =AD21*(1+W22) -> 85.872317 | AE22: =AE21*(1+X22) -> 106.95556 | AF22: =AF21*(1+Y22) -> 105.68529 | AG22: =AG21*(1+Z22) -> 106.95279 | AH22: =AH21*(1+AA22) -> 99.981502 | AI22: =AI21*(1+AB22) -> 100.53266 | AJ22: ='Data Descriptors 2'!$V22-'Data Descriptors 2'!$X22 -> -0.1139133 | AK22: ='Data Descriptors 2'!$V22-'Data Descriptors 2'!$Y22 -> -0.12429066
A23: 1930 | B23: =('[1]S&P 500 & Raw Data'!B6-'[1]S&P 500 & Raw Data'!B5+'[1]S&P 500 & Raw Data'!C6)/'[1]S&P 500 & Raw Data'!B5 -> -0.25123636 | C23: ='[1]Small Cap'!B4 -> -0.5003 | D23: 0.0455 | E23: ='[1]S&P 500 & Raw Data'!F6 -> 0.045409314 | F23: ='[1]S&P 500 & Raw Data'!J6 -> 0.0053978095 | G23: ='[1]Home Prices'!B6/'[1]Home Prices'!B5-1 -> -0.043 | H23: ='[1]Gold Prices'!B5/'[1]Gold Prices'!B4-1 -> 0.00096946195 | I23: =I22*(1+B23) -> 98.745288 | J23: =J22*(1+C23) -> 42.662362 | K23: =K22*(1+D23) -> 111.17568 | L23: =L22*(1+E23) -> 109.84575 | M23: =M22*(1+F23) -> 106.90854 | N23: =N22*(1+G23) -> 95.129225 | O23: =O22*(1+H23) -> 100.04845 | P23: =B23-D23 -> -0.29673636 | Q23: =B23-E23 -> -0.29664568 | R23: ='Data Descriptors 2'!$C23-'Data Descriptors 2'!$B23 -> -0.24906364 | S23: =B23-F23 -> -0.25663417 | U23: ='[1]Inflation Rate'!C28 -> -0.0639535 | V23: =(1+B23)/(1+$U23)-1 -> -0.20007859 | W23: =(1+C23)/(1+$U23)-1 -> -0.466159 | X23: =(1+D23)/(1+$U23)-1 -> 0.11693169 | Y23: =(1+E23)/(1+$U23)-1 -> 0.11683481 | Z23: =(1+F23)/(1+$U23)-1 -> 0.074089599 | AA23: =(1+G23)/(1+$U23)-1 -> 0.022385106 | AB23: =(1+H23)/(1+$U23)-1 -> 0.069358693 | AC23: =AC22*(1+V23) -> 106.10518 | AD23: =AD22*(1+W23) -> 45.842164 | AE23: =AE22*(1+X23) -> 119.46206 | AF23: =AF22*(1+Y23) -> 118.03301 | AG23: =AG22*(1+Z23) -> 114.87688 | AH23: =AH22*(1+AA23) -> 102.2196 | AI23: =AI22*(1+AB23) -> 107.50547 | AJ23: ='Data Descriptors 2'!$V23-'Data Descriptors 2'!$X23 -> -0.31701028 | AK23: ='Data Descriptors 2'!$V23-'Data Descriptors 2'!$Y23 -> -0.3169134
A24: 1931 | B24: =('[1]S&P 500 & Raw Data'!B7-'[1]S&P 500 & Raw Data'!B6+'[1]S&P 500 & Raw Data'!C7)/'[1]S&P 500 & Raw Data'!B6 -> -0.43837549 | C24: ='[1]Small Cap'!B5 -> -0.4466 | D24: 0.0231 | E24: ='[1]S&P 500 & Raw Data'!F7 -> -0.02558856 | F24: ='[1]S&P 500 & Raw Data'!J7 -> -0.15680775 | G24: ='[1]Home Prices'!B7/'[1]Home Prices'!B6-1 -> -0.081504702 | H24: ='[1]Gold Prices'!B6/'[1]Gold Prices'!B5-1 -> -0.17384988 | I24: =I23*(1+B24) -> 55.457774 | J24: =J23*(1+C24) -> 23.609351 | K24: =K23*(1+D24) -> 113.74383 | L24: =L23*(1+E24) -> 107.03496 | M24: =M23*(1+F24) -> 90.144455 | N24: =N23*(1+G24) -> 87.375746 | O24: =O23*(1+H24) -> 82.655039 | P24: =B24-D24 -> -0.46147549 | Q24: =B24-E24 -> -0.41278693 | R24: ='Data Descriptors 2'!$C24-'Data Descriptors 2'!$B24 -> -0.0082245111 | S24: =B24-F24 -> -0.28156774 | U24: ='[1]Inflation Rate'!C29 -> -0.0931677 | V24: =(1+B24)/(1+$U24)-1 -> -0.38067434 | W24: =(1+C24)/(1+$U24)-1 -> -0.38974384 | X24: =(1+D24)/(1+$U24)-1 -> 0.12821301 | Y24: =(1+E24)/(1+$U24)-1 -> 0.074522203 | Z24: =(1+F24)/(1+$U24)-1 -> -0.070178412 | AA24: =(1+G24)/(1+$U24)-1 -> 0.012861251 | AB24: =(1+H24)/(1+$U24)-1 -> -0.088971444 | AC24: =AC23*(1+V24) -> 65.713662 | AD24: =AD23*(1+W24) -> 27.975463 | AE24: =AE23*(1+X24) -> 134.77865 | AF24: =AF23*(1+Y24) -> 126.82909 | AG24: =AG23*(1+Z24) -> 106.815 | AH24: =AH23*(1+AA24) -> 103.53427 | AI24: =AI23*(1+AB24) -> 97.940557 | AJ24: ='Data Descriptors 2'!$V24-'Data Descriptors 2'!$X24 -> -0.50888735 | AK24: ='Data Descriptors 2'!$V24-'Data Descriptors 2'!$Y24 -> -0.45519654
A25: 1932 | B25: =('[1]S&P 500 & Raw Data'!B8-'[1]S&P 500 & Raw Data'!B7+'[1]S&P 500 & Raw Data'!C8)/'[1]S&P 500 & Raw Data'!B7 -> -0.086423645 | C25: ='[1]Small Cap'!B6 -> 0.2049 | D25: 0.0107 | E25: ='[1]S&P 500 & Raw Data'!F8 -> 0.08790307 | F25: ='[1]S&P 500 & Raw Data'!J8 -> 0.23589602 | G25: ='[1]Home Prices'!B8/'[1]Home Prices'!B7-1 -> -0.10466439 | H25: ='[1]Gold Prices'!B7/'[1]Gold Prices'!B6-1 -> 0.21277843 | I25: =I24*(1+B25) -> 50.664911 | J25: =J24*(1+C25) -> 28.446907 | K25: =K24*(1+D25) -> 114.96089 | L25: =L24*(1+E25) -> 116.44366 | M25: =M24*(1+F25) -> 111.40917 | N25: =N24*(1+G25) -> 78.230616 | O25: =O24*(1+H25) -> 100.24225 | P25: =B25-D25 -> -0.097123645 | Q25: =B25-E25 -> -0.17432672 | R25: ='Data Descriptors 2'!$C25-'Data Descriptors 2'!$B25 -> 0.29132365 | S25: =B25-F25 -> -0.32231966 | U25: ='[1]Inflation Rate'!C30 -> -0.1027397 | V25: =(1+B25)/(1+$U25)-1 -> 0.018184305 | W25: =(1+C25)/(1+$U25)-1 -> 0.34286561 | X25: =(1+D25)/(1+$U25)-1 -> 0.12642897 | Y25: =(1+E25)/(1+$U25)-1 -> 0.21247209 | Z25: =(1+F25)/(1+$U25)-1 -> 0.37741079 | AA25: =(1+G25)/(1+$U25)-1 -> -0.0021450758 | AB25: =(1+H25)/(1+$U25)-1 -> 0.35164615 | AC25: =AC24*(1+V25) -> 66.908619 | AD25: =AD24*(1+W25) -> 37.567287 | AE25: =AE24*(1+X25) -> 151.81858 | AF25: =AF24*(1+Y25) -> 153.77673 | AG25: =AG24*(1+Z25) -> 147.12814 | AH25: =AH24*(1+AA25) -> 103.31218 | AI25: =AI24*(1+AB25) -> 132.38098 | AJ25: ='Data Descriptors 2'!$V25-'Data Descriptors 2'!$X25 -> -0.10824467 | AK25: ='Data Descriptors 2'!$V25-'Data Descriptors 2'!$Y25 -> -0.19428778
A26: 1933 | B26: =('[1]S&P 500 & Raw Data'!B9-'[1]S&P 500 & Raw Data'!B8+'[1]S&P 500 & Raw Data'!C9)/'[1]S&P 500 & Raw Data'!B8 -> 0.49982225 | C26: ='[1]Small Cap'!B7 -> 1.4834 | D26: 0.0096 | E26: ='[1]S&P 500 & Raw Data'!F9 -> 0.018552721 | F26: ='[1]S&P 500 & Raw Data'!J9 -> 0.12966894 | G26: ='[1]Home Prices'!B9/'[1]Home Prices'!B8-1 -> -0.038119441 | H26: ='[1]Gold Prices'!B8/'[1]Gold Prices'!B7-1 -> 0.27259546 | I26: =I25*(1+B26) -> 75.988361 | J26: =J25*(1+C26) -> 70.645049 | K26: =K25*(1+D26) -> 116.06452 | L26: =L25*(1+E26) -> 118.60401 | M26: =M25*(1+F26) -> 125.85548 | N26: =N25*(1+G26) -> 75.248509 | O26: =O25*(1+H26) -> 127.56783 | P26: =B26-D26 -> 0.49022225 | Q26: =B26-E26 -> 0.48126953 | R26: ='Data Descriptors 2'!$C26-'Data Descriptors 2'!$B26 -> 0.98357775 | S26: =B26-F26 -> 0.37015332 | U26: ='[1]Inflation Rate'!C31 -> 0.0076336 | V26: =(1+B26)/(1+$U26)-1 -> 0.48845995 | W26: =(1+C26)/(1+$U26)-1 -> 1.4645863 | X26: =(1+D26)/(1+$U26)-1 -> 0.001951503 | Y26: =(1+E26)/(1+$U26)-1 -> 0.0108364 | Z26: =(1+F26)/(1+$U26)-1 -> 0.12111083 | AA26: =(1+G26)/(1+$U26)-1 -> -0.045406426 | AB26: =(1+H26)/(1+$U26)-1 -> 0.26295457 | AC26: =AC25*(1+V26) -> 99.590799 | AD26: =AD25*(1+W26) -> 92.587823 | AE26: =AE25*(1+X26) -> 152.11485 | AF26: =AF25*(1+Y26) -> 155.44312 | AG26: =AG25*(1+Z26) -> 164.94695 | AH26: =AH25*(1+AA26) -> 98.621145 | AI26: =AI25*(1+AB26) -> 167.19116 | AJ26: ='Data Descriptors 2'!$V26-'Data Descriptors 2'!$X26 -> 0.48650844 | AK26: ='Data Descriptors 2'!$V26-'Data Descriptors 2'!$Y26 -> 0.47762355
A27: 1934 | B27: =('[1]S&P 500 & Raw Data'!B10-'[1]S&P 500 & Raw Data'!B9+'[1]S&P 500 & Raw Data'!C10)/'[1]S&P 500 & Raw Data'!B9 -> -0.011885657 | C27: ='[1]Small Cap'!B8 -> 0.2001 | D27: ='[1]T. Bill rates'!C12 -> 0.0027833333 | E27: ='[1]S&P 500 & Raw Data'!F10 -> 0.079634426 | F27: ='[1]S&P 500 & Raw Data'!J10 -> 0.18816429 | G27: ='[1]Home Prices'!B10/'[1]Home Prices'!B9-1 -> 0.029062087 | H27: ='[1]Gold Prices'!B9/'[1]Gold Prices'!B8-1 -> 0.31750855 | I27: =I26*(1+B27) -> 75.085189 | J27: =J26*(1+C27) -> 84.781123 | K27: =K26*(1+D27) -> 116.38756 | L27: =L26*(1+E27) -> 128.04897 | M27: =M26*(1+F27) -> 149.53699 | N27: =N26*(1+G27) -> 77.435388 | O27: =O26*(1+H27) -> 168.07171 | P27: =B27-D27 -> -0.01466899 | Q27: =B27-E27 -> -0.091520083 | R27: ='Data Descriptors 2'!$C27-'Data Descriptors 2'!$B27 -> 0.21198566 | S27: =B27-F27 -> -0.20004995 | U27: ='[1]Inflation Rate'!C32 -> 0.0151515 | V27: =(1+B27)/(1+$U27)-1 -> -0.026633618 | W27: =(1+C27)/(1+$U27)-1 -> 0.18218808 | X27: =(1+D27)/(1+$U27)-1 -> -0.012183567 | Y27: =(1+E27)/(1+$U27)-1 -> 0.063520495 | Z27: =(1+F27)/(1+$U27)-1 -> 0.17043051 | AA27: =(1+G27)/(1+$U27)-1 -> 0.013702967 | AB27: =(1+H27)/(1+$U27)-1 -> 0.29784426 | AC27: =AC26*(1+V27) -> 96.938336 | AD27: =AD26*(1+W27) -> 109.45622 | AE27: =AE26*(1+X27) -> 150.26155 | AF27: =AF26*(1+Y27) -> 165.31694 | AG27: =AG26*(1+Z27) -> 193.05894 | AH27: =AH26*(1+AA27) -> 99.972547 | AI27: =AI26*(1+AB27) -> 216.98809 | AJ27: ='Data Descriptors 2'!$V27-'Data Descriptors 2'!$X27 -> -0.01445005 | AK27: ='Data Descriptors 2'!$V27-'Data Descriptors 2'!$Y27 -> -0.090154113
A28: 1935 | B28: =('[1]S&P 500 & Raw Data'!B11-'[1]S&P 500 & Raw Data'!B10+'[1]S&P 500 & Raw Data'!C11)/'[1]S&P 500 & Raw Data'!B10 -> 0.46740421 | C28: ='[1]Small Cap'!B9 -> 0.5318 | D28: ='[1]T. Bill rates'!C13 -> 0.001675 | E28: ='[1]S&P 500 & Raw Data'!F11 -> 0.044720477 | F28: ='[1]S&P 500 & Raw Data'!J11 -> 0.13307732 | G28: ='[1]Home Prices'!B11/'[1]Home Prices'!B10-1 -> 0.097658337 | H28: ='[1]Gold Prices'!B10/'[1]Gold Prices'!B9-1 -> 0.0043240127 | I28: =I27*(1+B28) -> 110.18032 | J28: =J27*(1+C28) -> 129.86772 | K28: =K27*(1+D28) -> 116.58251 | L28: =L27*(1+E28) -> 133.77538 | M28: =M27*(1+F28) -> 169.43697 | N28: =N27*(1+G28) -> 84.997599 | O28: =O27*(1+H28) -> 168.79845 | P28: =B28-D28 -> 0.46572921 | Q28: =B28-E28 -> 0.42268373 | R28: ='Data Descriptors 2'!$C28-'Data Descriptors 2'!$B28 -> 0.064395789 | S28: =B28-F28 -> 0.33432689 | U28: ='[1]Inflation Rate'!C33 -> 0.0298507 | V28: =(1+B28)/(1+$U28)-1 -> 0.42487082 | W28: =(1+C28)/(1+$U28)-1 -> 0.48740007 | X28: =(1+D28)/(1+$U28)-1 -> -0.027359014 | Y28: =(1+E28)/(1+$U28)-1 -> 0.01443877 | Z28: =(1+F28)/(1+$U28)-1 -> 0.10023455 | AA28: =(1+G28)/(1+$U28)-1 -> 0.065842201 | AB28: =(1+H28)/(1+$U28)-1 -> -0.024786784 | AC28: =AC27*(1+V28) -> 138.12461 | AD28: =AD27*(1+W28) -> 162.80519 | AE28: =AE27*(1+X28) -> 146.15054 | AF28: =AF27*(1+Y28) -> 167.70392 | AG28: =AG27*(1+Z28) -> 212.41011 | AH28: =AH27*(1+AA28) -> 106.55496 | AI28: =AI27*(1+AB28) -> 211.60965 | AJ28: ='Data Descriptors 2'!$V28-'Data Descriptors 2'!$X28 -> 0.45222983 | AK28: ='Data Descriptors 2'!$V28-'Data Descriptors 2'!$Y28 -> 0.41043205
A29: 1936 | B29: =('[1]S&P 500 & Raw Data'!B12-'[1]S&P 500 & Raw Data'!B11+'[1]S&P 500 & Raw Data'!C12)/'[1]S&P 500 & Raw Data'!B11 -> 0.3194341 | C29: ='[1]Small Cap'!B10 -> 0.9282 | D29: ='[1]T. Bill rates'!C14 -> 0.001725 | E29: ='[1]S&P 500 & Raw Data'!F12 -> 0.050178754 | F29: ='[1]S&P 500 & Raw Data'!J12 -> 0.11383816 | G29: ='[1]Home Prices'!B12/'[1]Home Prices'!B11-1 -> 0.032186015 | H29: ='[1]Gold Prices'!B11/'[1]Gold Prices'!B10-1 -> 0.00086107922 | I29: =I28*(1+B29) -> 145.37568 | J29: =J28*(1+C29) -> 250.41095 | K29: =K28*(1+D29) -> 116.78362 | L29: =L28*(1+E29) -> 140.48806 | M29: =M28*(1+F29) -> 188.72536 | N29: =N28*(1+G29) -> 87.733333 | O29: =O28*(1+H29) -> 168.9438 | P29: =B29-D29 -> 0.3177091 | Q29: =B29-E29 -> 0.26925535 | R29: ='Data Descriptors 2'!$C29-'Data Descriptors 2'!$B29 -> 0.6087659 | S29: =B29-F29 -> 0.20559594 | U29: ='[1]Inflation Rate'!C34 -> 0.0144928 | V29: =(1+B29)/(1+$U29)-1 -> 0.30058498 | W29: =(1+C29)/(1+$U29)-1 -> 0.9006542 | X29: =(1+D29)/(1+$U29)-1 -> -0.012585402 | Y29: =(1+E29)/(1+$U29)-1 -> 0.035176153 | Z29: =(1+F29)/(1+$U29)-1 -> 0.097926135 | AA29: =(1+G29)/(1+$U29)-1 -> 0.017440454 | AB29: =(1+H29)/(1+$U29)-1 -> -0.013436981 | AC29: =AC28*(1+V29) -> 179.64279 | AD29: =AD28*(1+W29) -> 309.43637 | AE29: =AE28*(1+X29) -> 144.31118 | AF29: =AF28*(1+Y29) -> 173.60309 | AG29: =AG28*(1+Z29) -> 233.21061 | AH29: =AH28*(1+AA29) -> 108.41333 | AI29: =AI28*(1+AB29) -> 208.76625 | AJ29: ='Data Descriptors 2'!$V29-'Data Descriptors 2'!$X29 -> 0.31317039 | AK29: ='Data Descriptors 2'!$V29-'Data Descriptors 2'!$Y29 -> 0.26540883
A30: 1937 | B30: =('[1]S&P 500 & Raw Data'!B13-'[1]S&P 500 & Raw Data'!B12+'[1]S&P 500 & Raw Data'!C13)/'[1]S&P 500 & Raw Data'!B12 -> -0.35336729 | C30: ='[1]Small Cap'!B11 -> -0.5328 | D30: ='[1]T. Bill rates'!C15 -> 0.0027583333 | E30: ='[1]S&P 500 & Raw Data'!F13 -> 0.013791461 | F30: ='[1]S&P 500 & Raw Data'!J13 -> -0.044161917 | G30: ='[1]Home Prices'!B13/'[1]Home Prices'!B12-1 -> 0.025633912 | H30: ='[1]Gold Prices'!B12/'[1]Gold Prices'!B11-1 -> -0.0022942357 | I30: =I29*(1+B30) -> 94.004668 | J30: =J29*(1+C30) -> 116.99199 | K30: =K29*(1+D30) -> 117.10575 | L30: =L29*(1+E30) -> 142.4256 | M30: =M29*(1+F30) -> 180.39089 | N30: =N29*(1+G30) -> 89.982281 | O30: =O29*(1+H30) -> 168.5562 | P30: =B30-D30 -> -0.35612562 | Q30: =B30-E30 -> -0.36715875 | R30: ='Data Descriptors 2'!$C30-'Data Descriptors 2'!$B30 -> -0.17943271 | S30: =B30-F30 -> -0.30920537 | U30: ='[1]Inflation Rate'!C35 -> 0.0285714 | V30: =(1+B30)/(1+$U30)-1 -> -0.37132929 | W30: =(1+C30)/(1+$U30)-1 -> -0.54577777 | X30: =(1+D30)/(1+$U30)-1 -> -0.025096038 | Y30: =(1+E30)/(1+$U30)-1 -> -0.014369386 | Z30: =(1+F30)/(1+$U30)-1 -> -0.070712949 | AA30: =(1+G30)/(1+$U30)-1 -> -0.002855891 | AB30: =(1+H30)/(1+$U30)-1 -> -0.030008258 | AC30: =AC29*(1+V30) -> 112.93616 | AD30: =AD29*(1+W30) -> 140.55288 | AE30: =AE29*(1+X30) -> 140.68954 | AF30: =AF29*(1+Y30) -> 171.10852 | AG30: =AG29*(1+Z30) -> 216.7196 | AH30: =AH29*(1+AA30) -> 108.10371 | AI30: =AI29*(1+AB30) -> 202.50154 | AJ30: ='Data Descriptors 2'!$V30-'Data Descriptors 2'!$X30 -> -0.34623325 | AK30: ='Data Descriptors 2'!$V30-'Data Descriptors 2'!$Y30 -> -0.3569599
A31: 1938 | B31: =('[1]S&P 500 & Raw Data'!B14-'[1]S&P 500 & Raw Data'!B13+'[1]S&P 500 & Raw Data'!C14)/'[1]S&P 500 & Raw Data'!B13 -> 0.29282654 | C31: ='[1]Small Cap'!B12 -> 0.016 | D31: ='[1]T. Bill rates'!C16 -> 0.00065 | E31: ='[1]S&P 500 & Raw Data'!F14 -> 0.042132485 | F31: ='[1]S&P 500 & Raw Data'!J14 -> 0.092358817 | G31: ='[1]Home Prices'!B14/'[1]Home Prices'!B13-1 -> -0.0087368136 | H31: ='[1]Gold Prices'!B13/'[1]Gold Prices'!B12-1 -> 0.0017246335 | I31: =I30*(1+B31) -> 121.53173 | J31: =J30*(1+C31) -> 118.86387 | K31: =K30*(1+D31) -> 117.18187 | L31: =L30*(1+E31) -> 148.42634 | M31: =M30*(1+F31) -> 197.05158 | N31: =N30*(1+G31) -> 89.196123 | O31: =O30*(1+H31) -> 168.8469 | P31: =B31-D31 -> 0.29217654 | Q31: =B31-E31 -> 0.25069405 | R31: ='Data Descriptors 2'!$C31-'Data Descriptors 2'!$B31 -> -0.27682654 | S31: =B31-F31 -> 0.20046772 | U31: ='[1]Inflation Rate'!C36 -> -0.0277778 | V31: =(1+B31)/(1+$U31)-1 -> 0.32976447 | W31: =(1+C31)/(1+$U31)-1 -> 0.045028595 | X31: =(1+D31)/(1+$U31)-1 -> 0.029240024 | Y31: =(1+E31)/(1+$U31)-1 -> 0.071907724 | Z31: =(1+F31)/(1+$U31)-1 -> 0.12356909 | AA31: =(1+G31)/(1+$U31)-1 -> 0.019585015 | AB31: =(1+H31)/(1+$U31)-1 -> 0.030345361 | AC31: =AC30*(1+V31) -> 150.17849 | AD31: =AD30*(1+W31) -> 146.88178 | AE31: =AE30*(1+X31) -> 144.8033 | AF31: =AF30*(1+Y31) -> 183.41255 | AG31: =AG30*(1+Z31) -> 243.49945 | AH31: =AH30*(1+AA31) -> 110.22092 | AI31: =AI30*(1+AB31) -> 208.64652 | AJ31: ='Data Descriptors 2'!$V31-'Data Descriptors 2'!$X31 -> 0.30052445 | AK31: ='Data Descriptors 2'!$V31-'Data Descriptors 2'!$Y31 -> 0.25785675
A32: 1939 | B32: =('[1]S&P 500 & Raw Data'!B15-'[1]S&P 500 & Raw Data'!B14+'[1]S&P 500 & Raw Data'!C15)/'[1]S&P 500 & Raw Data'!B14 -> -0.010975647 | C32: ='[1]Small Cap'!B13 -> -0.0573 | D32: ='[1]T. Bill rates'!C17 -> 0.00045833333 | E32: ='[1]S&P 500 & Raw Data'!F15 -> 0.044122614 | F32: ='[1]S&P 500 & Raw Data'!J15 -> 0.079831378 | G32: ='[1]Home Prices'!B15/'[1]Home Prices'!B14-1 -> -0.013016072 | H32: ='[1]Gold Prices'!B14/'[1]Gold Prices'!B13-1 -> -0.012338594 | I32: =I31*(1+B32) -> 120.19784 | J32: =J31*(1+C32) -> 112.05297 | K32: =K31*(1+D32) -> 117.23557 | L32: =L31*(1+E32) -> 154.9753 | M32: =M31*(1+F32) -> 212.78248 | N32: =N31*(1+G32) -> 88.03514 | O32: =O31*(1+H32) -> 166.76357 | P32: =B32-D32 -> -0.01143398 | Q32: =B32-E32 -> -0.055098261 | R32: ='Data Descriptors 2'!$C32-'Data Descriptors 2'!$B32 -> -0.046324353 | S32: =B32-F32 -> -0.090807025 | U32: ='[1]Inflation Rate'!C37 -> 0 | V32: =(1+B32)/(1+$U32)-1 -> -0.010975647 | W32: =(1+C32)/(1+$U32)-1 -> -0.0573 | X32: =(1+D32)/(1+$U32)-1 -> 0.00045833333 | Y32: =(1+E32)/(1+$U32)-1 -> 0.044122614 | Z32: =(1+F32)/(1+$U32)-1 -> 0.079831378 | AA32: =(1+G32)/(1+$U32)-1 -> -0.013016072 | AB32: =(1+H32)/(1+$U32)-1 -> -0.012338594 | AC32: =AC31*(1+V32) -> 148.53019 | AD32: =AD31*(1+W32) -> 138.46545 | AE32: =AE31*(1+X32) -> 144.86967 | AF32: =AF31*(1+Y32) -> 191.50519 | AG32: =AG31*(1+Z32) -> 262.93835 | AH32: =AH31*(1+AA32) -> 108.78628 | AI32: =AI31*(1+AB32) -> 206.07212 | AJ32: ='Data Descriptors 2'!$V32-'Data Descriptors 2'!$X32 -> -0.01143398 | AK32: ='Data Descriptors 2'!$V32-'Data Descriptors 2'!$Y32 -> -0.055098261
A33: 1940 | B33: =('[1]S&P 500 & Raw Data'!B16-'[1]S&P 500 & Raw Data'!B15+'[1]S&P 500 & Raw Data'!C16)/'[1]S&P 500 & Raw Data'!B15 -> -0.10672873 | C33: ='[1]Small Cap'!B14 -> -0.3181 | D33: ='[1]T. Bill rates'!C18 -> 0.00035833333 | E33: ='[1]S&P 500 & Raw Data'!F16 -> 0.054024816 | F33: ='[1]S&P 500 & Raw Data'!J16 -> 0.086481372 | G33: ='[1]Home Prices'!B16/'[1]Home Prices'!B15-1 -> 0.033066077 | H33: ='[1]Gold Prices'!B15/'[1]Gold Prices'!B14-1 -> -0.016560139 | I33: =I32*(1+B33) -> 107.36928 | J33: =J32*(1+C33) -> 76.408918 | K33: =K32*(1+D33) -> 117.27758 | L33: =L32*(1+E33) -> 163.34781 | M33: =M32*(1+F33) -> 231.1842 | N33: =N32*(1+G33) -> 90.946116 | O33: =O32*(1+H33) -> 164.00194 | P33: =B33-D33 -> -0.10708707 | Q33: =B33-E33 -> -0.16075355 | R33: ='Data Descriptors 2'!$C33-'Data Descriptors 2'!$B33 -> -0.21137127 | S33: =B33-F33 -> -0.1932101 | U33: ='[1]Inflation Rate'!C38 -> 0.0071429 | V33: =(1+B33)/(1+$U33)-1 -> -0.11306403 | W33: =(1+C33)/(1+$U33)-1 -> -0.3229362 | X33: =(1+D33)/(1+$U33)-1 -> -0.0067364489 | Y33: =(1+E33)/(1+$U33)-1 -> 0.046549418 | Z33: =(1+F33)/(1+$U33)-1 -> 0.078775784 | AA33: =(1+G33)/(1+$U33)-1 -> 0.025739323 | AB33: =(1+H33)/(1+$U33)-1 -> -0.023534932 | AC33: =AC32*(1+V33) -> 131.73677 | AD33: =AD32*(1+W33) -> 93.749944 | AE33: =AE32*(1+X33) -> 143.89377 | AF33: =AF32*(1+Y33) -> 200.41965 | AG33: =AG32*(1+Z33) -> 283.65152 | AH33: =AH32*(1+AA33) -> 111.58636 | AI33: =AI32*(1+AB33) -> 201.22223 | AJ33: ='Data Descriptors 2'!$V33-'Data Descriptors 2'!$X33 -> -0.10632758 | AK33: ='Data Descriptors 2'!$V33-'Data Descriptors 2'!$Y33 -> -0.15961345
A34: 1941 | B34: =('[1]S&P 500 & Raw Data'!B17-'[1]S&P 500 & Raw Data'!B16+'[1]S&P 500 & Raw Data'!C17)/'[1]S&P 500 & Raw Data'!B16 -> -0.12771456 | C34: ='[1]Small Cap'!B15 -> -0.0554 | D34: ='[1]T. Bill rates'!C19 -> 0.0012916667 | E34: ='[1]S&P 500 & Raw Data'!F17 -> -0.020221976 | F34: ='[1]S&P 500 & Raw Data'!J17 -> 0.050071729 | G34: ='[1]Home Prices'!B17/'[1]Home Prices'!B16-1 -> -0.083846277 | H34: ='[1]Gold Prices'!B16/'[1]Gold Prices'!B15-1 -> 0 | I34: =I33*(1+B34) -> 93.656657 | J34: =J33*(1+C34) -> 72.175864 | K34: =K33*(1+D34) -> 117.42907 | L34: =L33*(1+E34) -> 160.0446 | M34: =M33*(1+F34) -> 242.75999 | N34: =N33*(1+G34) -> 83.320623 | O34: =O33*(1+H34) -> 164.00194 | P34: =B34-D34 -> -0.12900622 | Q34: =B34-E34 -> -0.10749258 | R34: ='Data Descriptors 2'!$C34-'Data Descriptors 2'!$B34 -> 0.072314556 | S34: =B34-F34 -> -0.17778628 | U34: ='[1]Inflation Rate'!C39 -> 0.0992908 | V34: =(1+B34)/(1+$U34)-1 -> -0.20650164 | W34: =(1+C34)/(1+$U34)-1 -> -0.14071873 | X34: =(1+D34)/(1+$U34)-1 -> -0.089147597 | Y34: =(1+E34)/(1+$U34)-1 -> -0.10871807 | Z34: =(1+F34)/(1+$U34)-1 -> -0.044773477 | AA34: =(1+G34)/(1+$U34)-1 -> -0.16659566 | AB34: =(1+H34)/(1+$U34)-1 -> -0.090322597 | AC34: =AC33*(1+V34) -> 104.53291 | AD34: =AD33*(1+W34) -> 80.557572 | AE34: =AE33*(1+X34) -> 131.06598 | AF34: =AF33*(1+Y34) -> 178.63041 | AG34: =AG33*(1+Z34) -> 270.95146 | AH34: =AH33*(1+AA34) -> 92.99656 | AI34: =AI33*(1+AB34) -> 183.04731 | AJ34: ='Data Descriptors 2'!$V34-'Data Descriptors 2'!$X34 -> -0.11735405 | AK34: ='Data Descriptors 2'!$V34-'Data Descriptors 2'!$Y34 -> -0.097783571
A35: 1942 | B35: =('[1]S&P 500 & Raw Data'!B18-'[1]S&P 500 & Raw Data'!B17+'[1]S&P 500 & Raw Data'!C18)/'[1]S&P 500 & Raw Data'!B17 -> 0.19173763 | C35: ='[1]Small Cap'!B16 -> 0.6179 | D35: ='[1]T. Bill rates'!C20 -> 0.003425 | E35: ='[1]S&P 500 & Raw Data'!F18 -> 0.022948682 | F35: ='[1]S&P 500 & Raw Data'!J18 -> 0.05179901 | G35: ='[1]Home Prices'!B18/'[1]Home Prices'!B17-1 -> 0.033330412 | H35: ='[1]Gold Prices'!B17/'[1]Gold Prices'!B16-1 -> 0 | I35: =I34*(1+B35) -> 111.61416 | J35: =J34*(1+C35) -> 116.77333 | K35: =K34*(1+D35) -> 117.83126 | L35: =L34*(1+E35) -> 163.71741 | M35: =M34*(1+F35) -> 255.33472 | N35: =N34*(1+G35) -> 86.097734 | O35: =O34*(1+H35) -> 164.00194 | P35: =B35-D35 -> 0.18831263 | Q35: =B35-E35 -> 0.16878895 | R35: ='Data Descriptors 2'!$C35-'Data Descriptors 2'!$B35 -> 0.42616237 | S35: =B35-F35 -> 0.13993862 | U35: ='[1]Inflation Rate'!C40 -> 0.0903226 | V35: =(1+B35)/(1+$U35)-1 -> 0.093013783 | W35: =(1+C35)/(1+$U35)-1 -> 0.48387275 | X35: =(1+D35)/(1+$U35)-1 -> -0.079698981 | Y35: =(1+E35)/(1+$U35)-1 -> -0.061792645 | Z35: =(1+F35)/(1+$U35)-1 -> -0.035332286 | AA35: =(1+G35)/(1+$U35)-1 -> -0.052270941 | AB35: =(1+H35)/(1+$U35)-1 -> -0.082840253 | AC35: =AC34*(1+V35) -> 114.25591 | AD35: =AD34*(1+W35) -> 119.53719 | AE35: =AE34*(1+X35) -> 120.62016 | AF35: =AF34*(1+Y35) -> 167.59236 | AG35: =AG34*(1+Z35) -> 261.37812 | AH35: =AH34*(1+AA35) -> 88.135543 | AI35: =AI34*(1+AB35) -> 167.88363 | AJ35: ='Data Descriptors 2'!$V35-'Data Descriptors 2'!$X35 -> 0.17271276 | AK35: ='Data Descriptors 2'!$V35-'Data Descriptors 2'!$Y35 -> 0.15480643
A36: 1943 | B36: =('[1]S&P 500 & Raw Data'!B19-'[1]S&P 500 & Raw Data'!B18+'[1]S&P 500 & Raw Data'!C19)/'[1]S&P 500 & Raw Data'!B18 -> 0.2506131 | C36: ='[1]Small Cap'!B17 -> 1.3797 | D36: ='[1]T. Bill rates'!C21 -> 0.0038 | E36: ='[1]S&P 500 & Raw Data'!F19 -> 0.0249 | F36: ='[1]S&P 500 & Raw Data'!J19 -> 0.080446701 | G36: ='[1]Home Prices'!B19/'[1]Home Prices'!B18-1 -> 0.1144626 | H36: ='[1]Gold Prices'!B18/'[1]Gold Prices'!B17-1 -> 0 | I36: =I35*(1+B36) -> 139.58613 | J36: =J35*(1+C36) -> 277.88549 | K36: =K35*(1+D36) -> 118.27902 | L36: =L35*(1+E36) -> 167.79397 | M36: =M35*(1+F36) -> 275.87555 | N36: =N35*(1+G36) -> 95.952704 | O36: =O35*(1+H36) -> 164.00194 | P36: =B36-D36 -> 0.2468131 | Q36: =B36-E36 -> 0.2257131 | R36: ='Data Descriptors 2'!$C36-'Data Descriptors 2'!$B36 -> 1.1290869 | S36: =B36-F36 -> 0.1701664 | U36: ='[1]Inflation Rate'!C41 -> 0.0295858 | V36: =(1+B36)/(1+$U36)-1 -> 0.21467594 | W36: =(1+C36)/(1+$U36)-1 -> 1.3113178 | X36: =(1+D36)/(1+$U36)-1 -> -0.025044829 | Y36: =(1+E36)/(1+$U36)-1 -> -0.0045511506 | Z36: =(1+F36)/(1+$U36)-1 -> 0.04939938 | AA36: =(1+G36)/(1+$U36)-1 -> 0.082437811 | AB36: =(1+H36)/(1+$U36)-1 -> -0.028735633 | AC36: =AC35*(1+V36) -> 138.7839 | AD36: =AD35*(1+W36) -> 276.28843 | AE36: =AE35*(1+X36) -> 117.59925 | AF36: =AF35*(1+Y36) -> 166.82962 | AG36: =AG35*(1+Z36) -> 274.29004 | AH36: =AH35*(1+AA36) -> 95.401244 | AI36: =AI35*(1+AB36) -> 163.05938 | AJ36: ='Data Descriptors 2'!$V36-'Data Descriptors 2'!$X36 -> 0.23972077 | AK36: ='Data Descriptors 2'!$V36-'Data Descriptors 2'!$Y36 -> 0.21922709
A37: 1944 | B37: =('[1]S&P 500 & Raw Data'!B20-'[1]S&P 500 & Raw Data'!B19+'[1]S&P 500 & Raw Data'!C20)/'[1]S&P 500 & Raw Data'!B19 -> 0.19030677 | C37: ='[1]Small Cap'!B18 -> 0.6973 | D37: ='[1]T. Bill rates'!C22 -> 0.0038 | E37: ='[1]S&P 500 & Raw Data'!F20 -> 0.025776112 | F37: ='[1]S&P 500 & Raw Data'!J20 -> 0.065658636 | G37: ='[1]Home Prices'!B20/'[1]Home Prices'!B19-1 -> 0.16584227 | H37: ='[1]Gold Prices'!B19/'[1]Gold Prices'!B18-1 -> 0 | I37: =I36*(1+B37) -> 166.15032 | J37: =J36*(1+C37) -> 471.65505 | K37: =K36*(1+D37) -> 118.72848 | L37: =L36*(1+E37) -> 172.11905 | M37: =M36*(1+F37) -> 293.98917 | N37: =N36*(1+G37) -> 111.86572 | O37: =O36*(1+H37) -> 164.00194 | P37: =B37-D37 -> 0.18650677 | Q37: =B37-E37 -> 0.16453066 | R37: ='Data Descriptors 2'!$C37-'Data Descriptors 2'!$B37 -> 0.50699323 | S37: =B37-F37 -> 0.12464813 | U37: ='[1]Inflation Rate'!C42 -> 0.0229885 | V37: =(1+B37)/(1+$U37)-1 -> 0.16355831 | W37: =(1+C37)/(1+$U37)-1 -> 0.65915844 | X37: =(1+D37)/(1+$U37)-1 -> -0.018757298 | Y37: =(1+E37)/(1+$U37)-1 -> 0.0027249686 | Z37: =(1+F37)/(1+$U37)-1 -> 0.041711257 | AA37: =(1+G37)/(1+$U37)-1 -> 0.13964358 | AB37: =(1+H37)/(1+$U37)-1 -> -0.022471905 | AC37: =AC36*(1+V37) -> 161.48316 | AD37: =AD36*(1+W37) -> 458.40627 | AE37: =AE36*(1+X37) -> 115.3934 | AF37: =AF36*(1+Y37) -> 167.28423 | AG37: =AG36*(1+Z37) -> 285.73102 | AH37: =AH36*(1+AA37) -> 108.72341 | AI37: =AI36*(1+AB37) -> 159.39513 | AJ37: ='Data Descriptors 2'!$V37-'Data Descriptors 2'!$X37 -> 0.18231561 | AK37: ='Data Descriptors 2'!$V37-'Data Descriptors 2'!$Y37 -> 0.16083334
A38: 1945 | B38: =('[1]S&P 500 & Raw Data'!B21-'[1]S&P 500 & Raw Data'!B20+'[1]S&P 500 & Raw Data'!C21)/'[1]S&P 500 & Raw Data'!B20 -> 0.35821084 | C38: ='[1]Small Cap'!B19 -> 0.9109 | D38: ='[1]T. Bill rates'!C23 -> 0.0038 | E38: ='[1]S&P 500 & Raw Data'!F21 -> 0.038044173 | F38: ='[1]S&P 500 & Raw Data'!J21 -> 0.067998655 | G38: ='[1]Home Prices'!B21/'[1]Home Prices'!B20-1 -> 0.11777376 | H38: ='[1]Gold Prices'!B20/'[1]Gold Prices'!B19-1 -> 0.025406204 | I38: =I37*(1+B38) -> 225.66717 | J38: =J37*(1+C38) -> 901.28563 | K38: =K37*(1+D38) -> 119.17965 | L38: =L37*(1+E38) -> 178.66717 | M38: =M37*(1+F38) -> 313.98003 | N38: =N37*(1+G38) -> 125.04057 | O38: =O37*(1+H38) -> 168.1686 | P38: =B38-D38 -> 0.35441084 | Q38: =B38-E38 -> 0.32016667 | R38: ='Data Descriptors 2'!$C38-'Data Descriptors 2'!$B38 -> 0.55268916 | S38: =B38-F38 -> 0.29021219 | U38: ='[1]Inflation Rate'!C43 -> 0.0224719 | V38: =(1+B38)/(1+$U38)-1 -> 0.32836007 | W38: =(1+C38)/(1+$U38)-1 -> 0.86890222 | X38: =(1+D38)/(1+$U38)-1 -> -0.018261529 | Y38: =(1+E38)/(1+$U38)-1 -> 0.015230026 | Z38: =(1+F38)/(1+$U38)-1 -> 0.044526167 | AA38: =(1+G38)/(1+$U38)-1 -> 0.093207319 | AB38: =(1+H38)/(1+$U38)-1 -> 0.0028698137 | AC38: =AC37*(1+V38) -> 214.50779 | AD38: =AD37*(1+W38) -> 856.7165 | AE38: =AE37*(1+X38) -> 113.28614 | AF38: =AF37*(1+Y38) -> 169.83197 | AG38: =AG37*(1+Z38) -> 298.45353 | AH38: =AH37*(1+AA38) -> 118.85723 | AI38: =AI37*(1+AB38) -> 159.85256 | AJ38: ='Data Descriptors 2'!$V38-'Data Descriptors 2'!$X38 -> 0.3466216 | AK38: ='Data Descriptors 2'!$V38-'Data Descriptors 2'!$Y38 -> 0.31313004
... A52: 1959 | B52: =('[1]S&P 500 & Raw Data'!B35-'[1]S&P 500 & Raw Data'!B34+'[1]S&P 500 & Raw Data'!C35)/'[1]S&P 500 & Raw Data'!B34 -> 0.12056457 | C52: ='[1]Small Cap'!B33 -> 0.1274 | D52: ='[1]T. Bill rates'!C37 -> 0.033860159 | E52: ='[1]S&P 500 & Raw Data'!F35 -> -0.026466313 | F52: ='[1]S&P 500 & Raw Data'!J35 -> 0.015743431 | G52: ='[1]Home Prices'!B35/'[1]Home Prices'!B34-1 -> 0.0010952903 | H52: ='[1]Gold Prices'!B34/'[1]Gold Prices'!B33-1 -> 0 | I52: =I51*(1+B52) -> 1608.9516 | J52: =J51*(1+C52) -> 4822.1565 | K52: =K51*(1+D52) -> 149.84231 | L52: =L51*(1+E52) -> 214.55509 | M52: =M51*(1+F52) -> 440.94935 | N52: =N51*(1+G52) -> 259.31167 | O52: =O51*(1+H52) -> 170.05814 | P52: =B52-D52 -> 0.086704412 | Q52: =B52-E52 -> 0.14703088 | R52: ='Data Descriptors 2'!$C52-'Data Descriptors 2'!$B52 -> 0.0068354284 | S52: =B52-F52 -> 0.10482114 | U52: ='[1]Inflation Rate'!C57 -> 0.017301 | V52: =(1+B52)/(1+$U52)-1 -> 0.10150739 | W52: =(1+C52)/(1+$U52)-1 -> 0.10822657 | X52: =(1+D52)/(1+$U52)-1 -> 0.016277542 | Y52: =(1+E52)/(1+$U52)-1 -> -0.043022972 | Z52: =(1+F52)/(1+$U52)-1 -> -0.0015310799 | AA52: =(1+G52)/(1+$U52)-1 -> -0.015930103 | AB52: =(1+H52)/(1+$U52)-1 -> -0.017006766 | AC52: =AC51*(1+V52) -> 946.76414 | AD52: =AD51*(1+W52) -> 2837.5277 | AE52: =AE51*(1+X52) -> 88.172525 | AF52: =AF51*(1+Y52) -> 126.25182 | AG52: =AG51*(1+Z52) -> 259.47022 | AH52: =AH51*(1+AA52) -> 152.58817 | AI52: =AI51*(1+AB52) -> 100.06823 | AJ52: ='Data Descriptors 2'!$V52-'Data Descriptors 2'!$X52 -> 0.085229851 | AK52: ='Data Descriptors 2'!$V52-'Data Descriptors 2'!$Y52 -> 0.14453036
A53: 1960 | B53: =('[1]S&P 500 & Raw Data'!B36-'[1]S&P 500 & Raw Data'!B35+'[1]S&P 500 & Raw Data'!C36)/'[1]S&P 500 & Raw Data'!B35 -> 0.0033653531 | C53: ='[1]Small Cap'!B34 -> -0.0349 | D53: ='[1]T. Bill rates'!C38 -> 0.028729719 | E53: ='[1]S&P 500 & Raw Data'!F36 -> 0.11639504 | F53: ='[1]S&P 500 & Raw Data'!J36 -> 0.066631872 | G53: ='[1]Home Prices'!B36/'[1]Home Prices'!B35-1 -> 0.0076586433 | H53: ='[1]Gold Prices'!B35/'[1]Gold Prices'!B34-1 -> 0.0048433048 | I53: =I52*(1+B53) -> 1614.3663 | J53: =J52*(1+C53) -> 4653.8633 | K53: =K52*(1+D53) -> 154.14724 | L53: =L52*(1+E53) -> 239.52824 | M53: =M52*(1+F53) -> 470.33063 | N53: =N52*(1+G53) -> 261.29765 | O53: =O52*(1+H53) -> 170.88178 | P53: =B53-D53 -> -0.025364366 | Q53: =B53-E53 -> -0.11302968 | R53: ='Data Descriptors 2'!$C53-'Data Descriptors 2'!$B53 -> -0.038265353 | S53: =B53-F53 -> -0.063266518 | T53: =((I53/100)^(1/(A53-$A$21+1)))-((L53/100)^(1/(A53-$A$21+1))) -> 0.061119788 | U53: ='[1]Inflation Rate'!C58 -> 0.0136054 | V53: =(1+B53)/(1+$U53)-1 -> -0.010102597 | W53: =(1+C53)/(1+$U53)-1 -> -0.047854323 | X53: =(1+D53)/(1+$U53)-1 -> 0.014921309 | Y53: =(1+E53)/(1+$U53)-1 -> 0.10140991 | Z53: =(1+F53)/(1+$U53)-1 -> 0.052314709 | AA53: =(1+G53)/(1+$U53)-1 -> -0.0058669347 | AB53: =(1+H53)/(1+$U53)-1 -> -0.0086444835 | AC53: =AC52*(1+V53) -> 937.19936 | AD53: =AD52*(1+W53) -> 2701.7398 | AE53: =AE52*(1+X53) -> 89.488175 | AF53: =AF52*(1+Y53) -> 139.055 | AG53: =AG52*(1+Z53) -> 273.04433 | AH53: =AH52*(1+AA53) -> 151.69295 | AI53: =AI52*(1+AB53) -> 99.203195 | AJ53: ='Data Descriptors 2'!$V53-'Data Descriptors 2'!$X53 -> -0.025023905 | AK53: ='Data Descriptors 2'!$V53-'Data Descriptors 2'!$Y53 -> -0.11151251
A54: 1961 | B54: =('[1]S&P 500 & Raw Data'!B37-'[1]S&P 500 & Raw Data'!B36+'[1]S&P 500 & Raw Data'!C37)/'[1]S&P 500 & Raw Data'!B36 -> 0.26637713 | C54: ='[1]Small Cap'!B35 -> 0.2983 | D54: ='[1]T. Bill rates'!C39 -> 0.0235249 | E54: ='[1]S&P 500 & Raw Data'!F37 -> 0.020609208 | F54: ='[1]S&P 500 & Raw Data'!J37 -> 0.051 | G54: ='[1]Home Prices'!B37/'[1]Home Prices'!B36-1 -> 0.009771987 | H54: ='[1]Gold Prices'!B36/'[1]Gold Prices'!B35-1 -> -0.00056705415 | I54: =I53*(1+B54) -> 2044.3966 | J54: =J53*(1+C54) -> 6042.1107 | K54: =K53*(1+D54) -> 157.77354 | L54: =L53*(1+E54) -> 244.46473 | M54: =M53*(1+F54) -> 494.31749 | N54: =N53*(1+G54) -> 263.85104 | O54: =O53*(1+H54) -> 170.78488 | P54: =B54-D54 -> 0.24285223 | Q54: =B54-E54 -> 0.24576792 | R54: ='Data Descriptors 2'!$C54-'Data Descriptors 2'!$B54 -> 0.03192287 | S54: =B54-F54 -> 0.21537713 | T54: =((I54/100)^(1/(A54-$A$21+1)))-((L54/100)^(1/(A54-$A$21+1))) -> 0.066173592 | U54: ='[1]Inflation Rate'!C59 -> 0.0067114 | V54: =(1+B54)/(1+$U54)-1 -> 0.25793463 | W54: =(1+C54)/(1+$U54)-1 -> 0.28964468 | X54: =(1+D54)/(1+$U54)-1 -> 0.01670141 | Y54: =(1+E54)/(1+$U54)-1 -> 0.013805156 | Z54: =(1+F54)/(1+$U54)-1 -> 0.043993343 | AA54: =(1+G54)/(1+$U54)-1 -> 0.0030401831 | AB54: =(1+H54)/(1+$U54)-1 -> -0.0072299312 | AC54: =AC53*(1+V54) -> 1178.9355 | AD54: =AD53*(1+W54) -> 3484.2843 | AE54: =AE53*(1+X54) -> 90.982753 | AF54: =AF53*(1+Y54) -> 140.97468 | AG54: =AG53*(1+Z54) -> 285.05646 | AH54: =AH53*(1+AA54) -> 152.15412 | AI54: =AI53*(1+AB54) -> 98.485963 | AJ54: ='Data Descriptors 2'!$V54-'Data Descriptors 2'!$X54 -> 0.24123322 | AK54: ='Data Descriptors 2'!$V54-'Data Descriptors 2'!$Y54 -> 0.24412947
